I'm sorry, but an uncaught exception occurred.

While running game code:
  File "game/script.rpy", line 55, in script
    a "Ca marche"
Exception: Sayer 'a' is not defined.

-- Full Traceback ------------------------------------------------------------

Full traceback:
  File "game/script.rpy", line 55, in script
    a "Ca marche"
  File "renpy/ast.py", line 680, in execute
    who = eval_who(self.who, self.who_fast)
  File "renpy/ast.py", line 574, in eval_who
    raise Exception("Sayer '%s' is not defined." % who)
Exception: Sayer 'a' is not defined.

Windows-10-10.0.18362
Ren'Py 7.4.2.1292
Robot et humain 1.0
Tue Feb 16 09:55:50 2021
